[2025-01-05 10:18:48,984] {taskinstance.py:1159} INFO - Dependencies all met for <TaskInstance: weather_data.cria_pasta manual__2025-01-05T13:18:46.886939+00:00 [queued]>
[2025-01-05 10:18:48,990] {taskinstance.py:1159} INFO - Dependencies all met for <TaskInstance: weather_data.cria_pasta manual__2025-01-05T13:18:46.886939+00:00 [queued]>
[2025-01-05 10:18:48,990] {taskinstance.py:1356} INFO - 
--------------------------------------------------------------------------------
[2025-01-05 10:18:48,990] {taskinstance.py:1357} INFO - Starting attempt 1 of 1
[2025-01-05 10:18:48,990] {taskinstance.py:1358} INFO - 
--------------------------------------------------------------------------------
[2025-01-05 10:18:49,004] {taskinstance.py:1377} INFO - Executing <Task(BashOperator): cria_pasta> on 2025-01-05 13:18:46.886939+00:00
[2025-01-05 10:18:49,009] {standard_task_runner.py:52} INFO - Started process 10237 to run task
[2025-01-05 10:18:49,021] {standard_task_runner.py:79} INFO - Running: ['airflow', 'tasks', 'run', 'weather_data', 'cria_pasta', 'manual__2025-01-05T13:18:46.886939+00:00', '--job-id', '43', '--raw', '--subdir', 'DAGS_FOLDER/weather_data.py', '--cfg-path', '/tmp/tmpy8fqdwba', '--error-file', '/tmp/tmpeylwmuaq']
[2025-01-05 10:18:49,022] {standard_task_runner.py:80} INFO - Job 43: Subtask cria_pasta
[2025-01-05 10:18:49,091] {task_command.py:370} INFO - Running <TaskInstance: weather_data.cria_pasta manual__2025-01-05T13:18:46.886939+00:00 [running]> on host daniel-virtual-machine
[2025-01-05 10:18:49,122] {taskinstance.py:1889} ERROR - Task failed with exception
Traceback (most recent call last):
  File "/home/daniel/Documents/Alura/python_apache_airflow_pipeline/venv/lib/python3.9/site-packages/airflow/models/taskinstance.py", line 1451, in _run_raw_task
    self._execute_task_with_callbacks(context, test_mode)
  File "/home/daniel/Documents/Alura/python_apache_airflow_pipeline/venv/lib/python3.9/site-packages/airflow/models/taskinstance.py", line 1555, in _execute_task_with_callbacks
    task_orig = self.render_templates(context=context)
  File "/home/daniel/Documents/Alura/python_apache_airflow_pipeline/venv/lib/python3.9/site-packages/airflow/models/taskinstance.py", line 2212, in render_templates
    rendered_task = self.task.render_template_fields(context)
  File "/home/daniel/Documents/Alura/python_apache_airflow_pipeline/venv/lib/python3.9/site-packages/airflow/models/baseoperator.py", line 1185, in render_template_fields
    self._do_render_template_fields(self, self.template_fields, context, jinja_env, set())
  File "/home/daniel/Documents/Alura/python_apache_airflow_pipeline/venv/lib/python3.9/site-packages/airflow/utils/session.py", line 71, in wrapper
    return func(*args, session=session, **kwargs)
  File "/home/daniel/Documents/Alura/python_apache_airflow_pipeline/venv/lib/python3.9/site-packages/airflow/models/abstractoperator.py", line 344, in _do_render_template_fields
    rendered_content = self.render_template(
  File "/home/daniel/Documents/Alura/python_apache_airflow_pipeline/venv/lib/python3.9/site-packages/airflow/models/abstractoperator.py", line 387, in render_template
    template = jinja_env.from_string(value)
  File "/home/daniel/Documents/Alura/python_apache_airflow_pipeline/venv/lib/python3.9/site-packages/jinja2/environment.py", line 1092, in from_string
    return cls.from_code(self, self.compile(source), gs, None)
  File "/home/daniel/Documents/Alura/python_apache_airflow_pipeline/venv/lib/python3.9/site-packages/jinja2/environment.py", line 757, in compile
    self.handle_exception(source=source_hint)
  File "/home/daniel/Documents/Alura/python_apache_airflow_pipeline/venv/lib/python3.9/site-packages/jinja2/environment.py", line 925, in handle_exception
    raise rewrite_traceback_stack(source=source)
  File "<unknown>", line 1, in template
jinja2.exceptions.TemplateSyntaxError: unexpected end of template, expected ','.
[2025-01-05 10:18:49,134] {taskinstance.py:1395} INFO - Marking task as FAILED. dag_id=weather_data, task_id=cria_pasta, execution_date=20250105T131846, start_date=20250105T131848, end_date=20250105T131849
[2025-01-05 10:18:49,145] {standard_task_runner.py:92} ERROR - Failed to execute job 43 for task cria_pasta (unexpected end of template, expected ','.; 10237)
[2025-01-05 10:18:49,157] {local_task_job.py:156} INFO - Task exited with return code 1
[2025-01-05 10:18:49,188] {local_task_job.py:273} INFO - 0 downstream tasks scheduled from follow-on schedule check
