[2025-01-05 10:40:11,675] {taskinstance.py:1159} INFO - Dependencies all met for <TaskInstance: weather_data.extrai_dados manual__2025-01-05T13:40:02.859488+00:00 [queued]>
[2025-01-05 10:40:11,691] {taskinstance.py:1159} INFO - Dependencies all met for <TaskInstance: weather_data.extrai_dados manual__2025-01-05T13:40:02.859488+00:00 [queued]>
[2025-01-05 10:40:11,692] {taskinstance.py:1356} INFO - 
--------------------------------------------------------------------------------
[2025-01-05 10:40:11,692] {taskinstance.py:1357} INFO - Starting attempt 1 of 1
[2025-01-05 10:40:11,692] {taskinstance.py:1358} INFO - 
--------------------------------------------------------------------------------
[2025-01-05 10:40:11,724] {taskinstance.py:1377} INFO - Executing <Task(PythonOperator): extrai_dados> on 2025-01-05 13:40:02.859488+00:00
[2025-01-05 10:40:11,732] {standard_task_runner.py:52} INFO - Started process 17916 to run task
[2025-01-05 10:40:11,751] {standard_task_runner.py:79} INFO - Running: ['airflow', 'tasks', 'run', 'weather_data', 'extrai_dados', 'manual__2025-01-05T13:40:02.859488+00:00', '--job-id', '55', '--raw', '--subdir', 'DAGS_FOLDER/weather_data.py', '--cfg-path', '/tmp/tmp25xcdij9', '--error-file', '/tmp/tmp8qcybb6r']
[2025-01-05 10:40:11,752] {standard_task_runner.py:80} INFO - Job 55: Subtask extrai_dados
[2025-01-05 10:40:11,883] {task_command.py:370} INFO - Running <TaskInstance: weather_data.extrai_dados manual__2025-01-05T13:40:02.859488+00:00 [running]> on host daniel-virtual-machine
[2025-01-05 10:40:12,008] {taskinstance.py:1569} INFO - Exporting the following env vars:
AIRFLOW_CTX_DAG_OWNER=airflow
AIRFLOW_CTX_DAG_ID=weather_data
AIRFLOW_CTX_TASK_ID=extrai_dados
AIRFLOW_CTX_EXECUTION_DATE=2025-01-05T13:40:02.859488+00:00
AIRFLOW_CTX_TRY_NUMBER=1
AIRFLOW_CTX_DAG_RUN_ID=manual__2025-01-05T13:40:02.859488+00:00
[2025-01-05 10:40:12,011] {logging_mixin.py:115} INFO - https://weather.visualcrossing.com/VisualCrossingWebServices/rest/services/timeline/Boston/2024-12-30/2025-01-06?unitGroup=metric&include=days&key=X4TW9EDJ3EKJML6NRKZE29MKH&contentType=csv
[2025-01-05 10:40:12,032] {taskinstance.py:1889} ERROR - Task failed with exception
Traceback (most recent call last):
  File "/usr/lib/python3.9/urllib/request.py", line 1346, in do_open
    h.request(req.get_method(), req.selector, req.data, headers,
  File "/usr/lib/python3.9/http/client.py", line 1285, in request
    self._send_request(method, url, body, headers, encode_chunked)
  File "/usr/lib/python3.9/http/client.py", line 1331, in _send_request
    self.endheaders(body, encode_chunked=encode_chunked)
  File "/usr/lib/python3.9/http/client.py", line 1280, in endheaders
    self._send_output(message_body, encode_chunked=encode_chunked)
  File "/usr/lib/python3.9/http/client.py", line 1040, in _send_output
    self.send(msg)
  File "/usr/lib/python3.9/http/client.py", line 980, in send
    self.connect()
  File "/usr/lib/python3.9/http/client.py", line 1447, in connect
    super().connect()
  File "/usr/lib/python3.9/http/client.py", line 946, in connect
    self.sock = self._create_connection(
  File "/usr/lib/python3.9/socket.py", line 835, in create_connection
    for res in getaddrinfo(host, port, 0, SOCK_STREAM):
  File "/usr/lib/python3.9/socket.py", line 966, in getaddrinfo
    for res in _socket.getaddrinfo(host, port, family, type, proto, flags):
socket.gaierror: [Errno -3] Temporary failure in name resolution

During handling of the above exception, another exception occurred:

Traceback (most recent call last):
  File "/home/daniel/Documents/Alura/python_apache_airflow_pipeline/venv/lib/python3.9/site-packages/airflow/operators/python.py", line 171, in execute
    return_value = self.execute_callable()
  File "/home/daniel/Documents/Alura/python_apache_airflow_pipeline/venv/lib/python3.9/site-packages/airflow/operators/python.py", line 189, in execute_callable
    return self.python_callable(*self.op_args, **self.op_kwargs)
  File "/home/daniel/Documents/Alura/python_apache_airflow_pipeline/dags/weather_data.py", line 36, in extract_data
    data = pd.read_csv(URL)
  File "/home/daniel/Documents/Alura/python_apache_airflow_pipeline/venv/lib/python3.9/site-packages/pandas/io/parsers/readers.py", line 1026, in read_csv
    return _read(filepath_or_buffer, kwds)
  File "/home/daniel/Documents/Alura/python_apache_airflow_pipeline/venv/lib/python3.9/site-packages/pandas/io/parsers/readers.py", line 620, in _read
    parser = TextFileReader(filepath_or_buffer, **kwds)
  File "/home/daniel/Documents/Alura/python_apache_airflow_pipeline/venv/lib/python3.9/site-packages/pandas/io/parsers/readers.py", line 1620, in __init__
    self._engine = self._make_engine(f, self.engine)
  File "/home/daniel/Documents/Alura/python_apache_airflow_pipeline/venv/lib/python3.9/site-packages/pandas/io/parsers/readers.py", line 1880, in _make_engine
    self.handles = get_handle(
  File "/home/daniel/Documents/Alura/python_apache_airflow_pipeline/venv/lib/python3.9/site-packages/pandas/io/common.py", line 728, in get_handle
    ioargs = _get_filepath_or_buffer(
  File "/home/daniel/Documents/Alura/python_apache_airflow_pipeline/venv/lib/python3.9/site-packages/pandas/io/common.py", line 384, in _get_filepath_or_buffer
    with urlopen(req_info) as req:
  File "/home/daniel/Documents/Alura/python_apache_airflow_pipeline/venv/lib/python3.9/site-packages/pandas/io/common.py", line 289, in urlopen
    return urllib.request.urlopen(*args, **kwargs)
  File "/usr/lib/python3.9/urllib/request.py", line 214, in urlopen
    return opener.open(url, data, timeout)
  File "/usr/lib/python3.9/urllib/request.py", line 517, in open
    response = self._open(req, data)
  File "/usr/lib/python3.9/urllib/request.py", line 534, in _open
    result = self._call_chain(self.handle_open, protocol, protocol +
  File "/usr/lib/python3.9/urllib/request.py", line 494, in _call_chain
    result = func(*args)
  File "/usr/lib/python3.9/urllib/request.py", line 1389, in https_open
    return self.do_open(http.client.HTTPSConnection, req,
  File "/usr/lib/python3.9/urllib/request.py", line 1349, in do_open
    raise URLError(err)
urllib.error.URLError: <urlopen error [Errno -3] Temporary failure in name resolution>
[2025-01-05 10:40:12,048] {taskinstance.py:1395} INFO - Marking task as FAILED. dag_id=weather_data, task_id=extrai_dados, execution_date=20250105T134002, start_date=20250105T134011, end_date=20250105T134012
[2025-01-05 10:40:12,088] {standard_task_runner.py:92} ERROR - Failed to execute job 55 for task extrai_dados (<urlopen error [Errno -3] Temporary failure in name resolution>; 17916)
[2025-01-05 10:40:12,127] {local_task_job.py:156} INFO - Task exited with return code 1
[2025-01-05 10:40:12,195] {local_task_job.py:273} INFO - 0 downstream tasks scheduled from follow-on schedule check
